@patch("utility.get_cloudwatch_log_group_name")
@patch("utility.boto3.client")
@patch("utility.watchtower.CloudWatchLogHandler")
@patch("utility.logging.getLogger")
def test_log_unstored_query_info_success( 
    mock_watchtower_handler, 
    mock_boto_client, 
    mock_get_log_group,
    mock_get_logger,
    common_test_data
    ):
   """Test successful logging to CloudWatch"""
   from utility import log_unstored_query_info_to_cloudwatch
   mock_get_log_group.return_value = CLOUDWATCH_LOG_GROUP_NAME
   mock_logger = MagicMock()
   mock_get_logger.return_value = mock_logger
   common_query_data = common_test_data.copy()
   common_query_data.update({
            "query_id": "test_query_id",
            "status_code": 200
    })
   log_unstored_query_info_to_cloudwatch(**common_query_data)
   log_stream_name = f"{CLOUDWATCH_LOG_GROUP_NAME}/{common_query_data['user_id']}_{common_query_data['query_id']}"
   mock_watchtower_handler.assert_called_once_with(
       log_group_name= CLOUDWATCH_LOG_GROUP_NAME,
       log_stream_name=log_stream_name,
       boto3_client=mock_boto_client.return_value,
   )

   expected_log_data = common_query_data
   print(f"Expected log data: {expected_log_data}")
   mock_logger.info.assert_called_once_with(json.dumps(expected_log_data))


now i am getting this error see below,

FAILED tests/test_utility.py::test_log_unstored_query_info_success - AssertionError: expected call not found.

E           AssertionError: expected call not found.
E           Expected: getLogger(log_group_name='/aws/DDB/UserQueryInfo', log_stream_name='/aws/DDB/UserQueryInfo/test_123_test_query_id', boto3_client=<MagicMock name='CloudWatchLogHandler()' id='139642058333824'>)
E           Actual: getLogger('CloudWatchLogger')

/usr/lib/python3.9/unittest/mock.py:907: AssertionError

please fix this test case.
