def test_log_unstored_query_info_general_exception():
   """Test handling of a general exception"""
   from utility import log_unstored_query_info_to_cloudwatch
   with patch("utility.boto3.client", side_effect=Exception("General AWS Error")), \
    patch("utility.logging.error") as mock_logging_error:
       user_id = "user123"
       query_id = "1741854306879"
       email_id = "user123@dummy.com"
       query_text = "I want to see snow data"
       query_response = {     
                "total": 2, 
                "internal_data": "Testing internal data",
                "data": [ 
                    { 
                    "display_id": "event1",
                    "score": "70%"
                    }, 
                    { 
                    "display_id": "event2",
                    "score": "65%"
                    }
                ]
            }
       page = "event_session"
       status_code = 200
       error_msg = ""
       log_unstored_query_info_to_cloudwatch(
            user_id, 
            query_id, 
            email_id, 
            query_text, 
            query_response, 
            page, 
            status_code, 
            error_msg
        )
       mock_logging_error.assert_called_with("Error while logging query info to cloudwatch General AWS Error")

for the above test case getting the below error fix this test case

AssertionError: expected call not found.
E           Expected: error('Error while logging query info to cloudwatch General AWS Error')
E           Actual: error('Error while logging query info to cloudwatch An error occurred (UnrecognizedClientException) when calling the GetParameter operation: The security token included in the request is invalid.')

/usr/lib/python3.9/unittest/mock.py:907: AssertionError
